Workbook

Sheet Ficha para impressão
C3: ORDEM DE CARREGAMENTO
C5: MOTORISTA: | D5: =IFERROR(UPPER(VLOOKUP(M5,base!A:I,2,0)),"") -> PAULO ROBERTO SANTANA DA SILVA | H5: CPF: | I5: =IFERROR(UPPER(VLOOKUP(M5,base!A:I,3,0)),"") -> 036.643.915-43 | L5: Nº: | M5: 138
M6: ,
C7: PLACA CAVALO: | D7: =IFERROR(UPPER(VLOOKUP(M5,base!A:I,4,0)),"") -> PNU-6E63 | F7: PLACA CARRETA: | G7: =IFERROR(UPPER(VLOOKUP(M5,base!A:I,5,0)),"") -> GUI TRANSPORTE | I7: TIPO DE VEÍCULO: | J7: =IFERROR(UPPER(VLOOKUP(M5,base!A:I,7,0)),"") -> 0,75 | L7: CUBAGEM: | M7: =IFERROR(UPPER(VLOOKUP(M5,base!A:I,9,0)),"") -> 30M³
C9: CONTATO: | D9: =IFERROR(UPPER(VLOOKUP(M5,base!A:I,6,0)),"") -> 75 98371-8065 | J9: =IFERROR(UPPER(VLOOKUP(M5,base!A:I,8,0)),"") -> 10 PALETES
C11: CONFERENTE 1: | I11: AJUDANTES:
C13: DATA 1: | G13: HORA INICIO: | J13: HORA FINAL:
C15: CONFERENTE 2: | G15: QTD VOLS FEITA: | I15: AJUDANTES:
C17: DATA 2: | G17: HORA INICIO: | J17: HORA FINAL:
C19: DOCA | E19: TIPO DE CARGA: | G19: □ BATIDA □ PALETIZADA □ MISTA | J19: DESTINO: | K19: FEIRA DE SANTANA
C21: SETOR | D21: ORDEM DE ENTREGA | F21: NF | G21: OBSERVAÇÃO | I21: PRAZO | J21: CIDADE | K21: PESO (KG) | L21: CUBAGEM | M21: VOLUME
C22: FS1 | F22: 12634 | I22: AGENDA 31/07 | J22: FEIRA DE SANTANA | K22: 2978 | L22: 7.5 | M22: 300
C23: FS1 | F23: 12630 | I23: 46232 | J23: FEIRA DE SANTANA | K23: 1039.5 | L23: 3.465 | M23: 99
C24: FS1 | F24: 12638* | G24: EM SEPARAÇÃO | I24: 46233 | J24: FEIRA DE SANTANA | K24: 34.08 | L24: 0.1136 | M24: 24
C25: FS1 | F25: 12639* | G25: EM SEPARAÇÃO | I25: 46233 | J25: FEIRA DE SANTANA | K25: 573.5 | L25: 1.9116667 | M25: 81
C26: FS1 | F26: 12636* | G26: EM SEPARAÇÃO | I26: 46233 | J26: FEIRA DE SANTANA | K26: 39.4 | L26: 0.13133333 | M26: 5
C27: FS1 | F27: 12643* | G27: EM SEPARAÇÃO | I27: 46234 | J27: FEIRA DE SANTANA | K27: 2021.8 | L27: 6.7393333 | M27: 437
C28: FS1 | F28: 946581 | I28: 46232 | J28: FEIRA DE SANTANA | K28: 93 | L28: 0.4774 | M28: 2
C29: FS1 | F29: 946627 | I29: 46233 | J29: FEIRA DE SANTANA | K29: 49.85 | L29: 0.224 | M29: 1
C30: FS1 | F30: 946804 | I30: 46232 | J30: FEIRA DE SANTANA | K30: 99.7 | L30: 0.4479 | M30: 2
C31: FS1 | F31: 947113 | I31: 46237 | J31: CONCEICAO DO JACUIPE | K31: 49.85 | L31: 0.224 | M31: 1
C32: FS1 | F32: 947443 | I32: 46238 | J32: CONCEICAO DO JACUIPE | K32: 46.5 | L32: 0.2387 | M32: 1
C33: FS1 | F33: 947614 | I33: 46233 | J33: FEIRA DE SANTANA | K33: 199.4 | L33: 0.8959 | M33: 4
C34: FS1 | F34: 1148659 | I34: 46232 | J34: FEIRA DE SANTANA | K34: 61.04 | L34: 0.637 | M34: 4
C35: FS1 | F35: 947913 | I35: 46233 | J35: FEIRA DE SANTANA | K35: 46.5 | L35: 0.2387 | M35: 1
C36: FS1 | F36: 28015 | I36: 46233 | J36: FEIRA DE SANTANA | K36: 482 | L36: 0.7568 | M36: 1
C37: FS1 | F37: 43240 | I37: 46232 | J37: FEIRA DE SANTANA | K37: 108.6 | L37: 0.2839 | M37: 3
C38: FS1 | F38: 23185 | I38: 46232 | J38: FEIRA DE SANTANA | K38: 95 | L38: 0.2911 | M38: 4
C39: FS1 | F39: 948320 | G39: DESCARGA - 27/07 | I39: 46234 | J39: FEIRA DE SANTANA | K39: 299.1 | L39: 1.3438 | M39: 6
C40: FS1 | F40: 948664 | G40: DESCARGA - 27/07 | I40: 46234 | J40: FEIRA DE SANTANA | K40: 59.25 | L40: 0.2414 | M40: 1
C41: FS1 | F41: 949167 | G41: DESCARGA - 27/07 | I41: 46234 | J41: FEIRA DE SANTANA | K41: 46.5 | L41: 0.2387 | M41: 1
C42: FS1 | F42: 949327 | G42: DESCARGA - 27/07 | I42: 46234 | J42: FEIRA DE SANTANA | K42: 46.5 | L42: 0.2387 | M42: 1
C43: FS1 | F43: 949334* | G43: DESCARGA - 27/07 | I43: 46234 | J43: FEIRA DE SANTANA | K43: 117.3 | L43: 0.562 | M43: 4
C44: FS1 | F44: 949435 | G44: DESCARGA - 27/07 | I44: 46237 | J44: FEIRA DE SANTANA | K44: 49.85 | L44: 0.224 | M44: 1
C45: FS1 | F45: 949724 | G45: DESCARGA - 27/07 | I45: 46241 | J45: SAO GONCALO DOS CAMPOS | K45: 99.7 | L45: 0.4479 | M45: 2
C46: FS1 | F46: 949795 | G46: DESCARGA - 27/07 | I46: 46237 | J46: FEIRA DE SANTANA | K46: 49.85 | L46: 0.224 | M46: 1
C47: FS1 | F47: 949990 | G47: DESCARGA - 27/07 | I47: 46237 | J47: FEIRA DE SANTANA | K47: 99.7 | L47: 0.4479 | M47: 2
C48: FS1 | F48: 950274 | G48: DESCARGA - 27/07 | I48: 46237 | J48: FEIRA DE SANTANA | K48: 99.7 | L48: 0.4479 | M48: 2
C49: FS1 | F49: 293563 | G49: DESCARGA - 27/07 | I49: 46238 | J49: FEIRA DE SANTANA | K49: 89.602 | L49: 0.889 | M49: 26
K71: =SUM(K22:K70) -> 9074.772 | L71: =SUM(L22:L70) -> 29.881633 | M71: =SUM(M22:M70) -> 1017
...

Sheet base
A1: Ordem | B1: Motorista | C1: CPF | D1: Placa Cavalo | E1: Placa Carreta | F1: Contato | G1: Tipo de veículo | H1: Qntdd Pal. | I1: Cubagem | J1: Capacidade | K1: Buonny | L1: Valid. Buonny
A2: 1 | B2: ADEMILTON PEREIRA DOS SANTOS | C2: 90541022504 | D2: JSU4E56 | E2: AGREGADO | F2: 71 98857-1709 | G2: BONGO | H2: 02 PALLETS | I2: 6,5M³ | J2: 1500KG | K2: =VLOOKUP(Tabela2[[#This Row],[Motorista]],BUONNY!B2:D242,3,1) -> 46155 | L2: =IF(K2>$N$2,"ADEQUADO AO RISCO","DIVERGENTE") -> DIVERGENTE | N2: =TODAY() -> 46246
A3: 2 | B3: ADILTON OLIVEIRA DA MOTA JUNIOR | C3: 11029723559 | D3: NTQ8I12 | E3: AGREGADO | F3: 71 99121-1061 | G3: BONGO | H3: 02 PALLETS | I3: 6M³ | J3: 1500KG | K3: =VLOOKUP(Tabela2[[#This Row],[Motorista]],BUONNY!B3:D243,3,1) -> 46207 | L3: =IF(K3>$N$2,"ADEQUADO AO RISCO","DIVERGENTE") -> DIVERGENTE
A4: 3 | B4: ALAN DELON SOUSA DOS SANTOS | C4: 9115100529 | D4: NYW0F97 | E4: AVULSO | G4: BONGO | H4: 02 PALLETS | I4: 8M³ | J4: 1500KG | K4: =VLOOKUP(Tabela2[[#This Row],[Motorista]],BUONNY!B4:D244,3,1) -> 46321 | L4: =IF(K4>$N$2,"ADEQUADO AO RISCO","DIVERGENTE") -> ADEQUADO AO RISCO
A5: 4 | B5: ALAN LOBO ALMEIDA | C5: 1983960586 | D5: NYM5D86 | E5: AGREGADO | F5: 71 98621-6322 | G5: VUC | H5: 02 PALLETS | I5: 11M³ | J5: 1500KG | K5: =VLOOKUP(Tabela2[[#This Row],[Motorista]],BUONNY!B5:D245,3,1) -> 46340 | L5: =IF(K5>$N$2,"ADEQUADO AO RISCO","DIVERGENTE") -> ADEQUADO AO RISCO
A6: 5 | B6: ALEX DOS SANTOS LIMA | C6: 3946588506 | D6: MDN7088 | E6: AGREGADO | G6: TOCO | H6: 12 PALETES | I6: 40M³ | J6: 8.000KG | K6: =VLOOKUP(Tabela2[[#This Row],[Motorista]],BUONNY!B6:D246,3,1) -> 46155 | L6: =IF(K6>$N$2,"ADEQUADO AO RISCO","DIVERGENTE") -> DIVERGENTE
A7: 6 | B7: ANDERSON SACRAMENTO SOUZA | C7: 82875162500 | D7: JQB8A20 | E7: AGREGADO | F7: 71 98839-3390 | G7: 0.75 | H7: 08 PALETES | I7: 18M³ | J7: 3700KG | K7: =VLOOKUP(Tabela2[[#This Row],[Motorista]],BUONNY!B7:D247,3,1) -> 46389 | L7: =IF(K7>$N$2,"ADEQUADO AO RISCO","DIVERGENTE") -> ADEQUADO AO RISCO
A8: 7 | B8: ANTONIO HIGINO FERRIERA DO COUTO | C8: 39693643534 | D8: JPC2189 | E8: AGREGADO | F8: 71 99130-2271 | G8: 0.75 | H8: 08 PALETES | I8: 18M³ | J8: 4.000KG | K8: =VLOOKUP(Tabela2[[#This Row],[Motorista]],BUONNY!B8:D248,3,1) -> 46389 | L8: =IF(K8>$N$2,"ADEQUADO AO RISCO","DIVERGENTE") -> ADEQUADO AO RISCO
A9: 8 | B9: ANTONIO NERIS DE ARAUJO | C9: 28235584549 | D9: JQZ0383 | E9: AGREGADO | F9: 71 98733-3286 | G9: BONGO | H9: 03 PALLETS | I9: 8M³ | J9: 1500KG | K9: =VLOOKUP(Tabela2[[#This Row],[Motorista]],BUONNY!B9:D249,3,1) -> 46155 | L9: =IF(K9>$N$2,"ADEQUADO AO RISCO","DIVERGENTE") -> DIVERGENTE
A10: 9 | B10: DAVI DIAS DOS SANTOS | C10: 81614012504 | D10: PKA8F07 | E10: AVULSO | F10: 71 98507-4711 | G10: BONGO | H10: 03 PALLETS | I10: 8M³ | J10: 2.000 KG | K10: =VLOOKUP(Tabela2[[#This Row],[Motorista]],BUONNY!B10:D250,3,1) -> 46389 | L10: =IF(K10>$N$2,"ADEQUADO AO RISCO","DIVERGENTE") -> ADEQUADO AO RISCO
A11: 10 | B11: EDUARDO LIMA DA SILVA | C11: 85797056577 | D11: NZR4D82 | E11: AVULSO | F11: 71 98631-9388 | G11: TRUCK | H11: 16 PALETES | I11: 50M³ | J11: 8.000KG | K11: =VLOOKUP(Tabela2[[#This Row],[Motorista]],BUONNY!B11:D251,3,1) -> 46155 | L11: =IF(K11>$N$2,"ADEQUADO AO RISCO","DIVERGENTE") -> DIVERGENTE
A12: 11 | B12: ELIECE SANTOS TRINDADE | C12: 1823496598 | D12: OVC9379 | E12: AGREGADO | G12: BONGO | H12: 02 PALLETS | I12: 6,5M³ | J12: 1500KG | K12: =VLOOKUP(Tabela2[[#This Row],[Motorista]],BUONNY!B12:D252,3,1) -> 46155 | L12: =IF(K12>$N$2,"ADEQUADO AO RISCO","DIVERGENTE") -> DIVERGENTE
A13: 13 | B13: FABRICIO SANTANA LIMA | C13: 86846798579 | D13: OVD6F23 | E13: AVULSO | G13: FIORINO | H13: 01 PALETE | I13: 1,9M³ | J13: 600KG | K13: =VLOOKUP(Tabela2[[#This Row],[Motorista]],BUONNY!B14:D254,3,1) -> 46155 | L13: =IF(K13>$N$2,"ADEQUADO AO RISCO","DIVERGENTE") -> DIVERGENTE
A14: 14 | B14: FRANCISCO SOUZA | C14: 84498382587 | D14: OZK6977 | E14: AGREGADO | F14: 71 98875-5339 | G14: BONGO | H14: 02 PALLETS | I14: 6,5M³ | J14: 1500KG | K14: =VLOOKUP(Tabela2[[#This Row],[Motorista]],BUONNY!B15:D255,3,1) -> 46155 | L14: =IF(K14>$N$2,"ADEQUADO AO RISCO","DIVERGENTE") -> DIVERGENTE
A15: 15 | B15: FREDSON SILVA OLIVEIRA | C15: 3912249563 | D15: JKW3F65 | E15: AGREGADO | G15: 0.75 | H15: 08 PALETES | I15: 14M³ | J15: 3000KG | K15: =VLOOKUP(Tabela2[[#This Row],[Motorista]],BUONNY!B16:D256,3,1) -> 46343 | L15: =IF(K15>$N$2,"ADEQUADO AO RISCO","DIVERGENTE") -> ADEQUADO AO RISCO
A16: 16 | B16: GABRIEL DE ALMEIDA SILVA | C16: 4963341581 | D16: JOL4J67 | E16: AGREGADO | G16: 0.75 | H16: 12 PALETES | I16: 40M³ | J16: 8.000KG | K16: =VLOOKUP(Tabela2[[#This Row],[Motorista]],BUONNY!B17:D257,3,1) -> 46155 | L16: =IF(K16>$N$2,"ADEQUADO AO RISCO","DIVERGENTE") -> DIVERGENTE
A17: 17 | B17: GLEDVAN BARBOSA DE ALMEIDA | C17: 35742534515 | D17: OZI2044 | E17: AVULSO | F17: 71 98875-3522 | G17: BONGO | H17: 02 PALLETS | I17: 6,5M³ | J17: 1500KG | K17: =VLOOKUP(Tabela2[[#This Row],[Motorista]],BUONNY!B18:D258,3,1) -> 46155 | L17: =IF(K17>$N$2,"ADEQUADO AO RISCO","DIVERGENTE") -> DIVERGENTE
A18: 18 | B18: IRANILDO CUSTODIO DA SILVA | C18: 77068637515 | D18: JNW9962 | E18: AGREGADO | F18: 71 98529-3225 | G18: 0.75 | H18: 06 PALETES | I18: 13M³ | J18: 3200KG | K18: =VLOOKUP(Tabela2[[#This Row],[Motorista]],BUONNY!B19:D259,3,1) -> 46389 | L18: =IF(K18>$N$2,"ADEQUADO AO RISCO","DIVERGENTE") -> ADEQUADO AO RISCO
A19: 19 | B19: JOILSON SOARES DE OLIVEIRA | C19: 66846978534 | D19: JNW5705 | E19: AGREGADO | G19: 0.75 | H19: 6 PALETES | I19: 13M³ | J19: 3.000KG | K19: =VLOOKUP(Tabela2[[#This Row],[Motorista]],BUONNY!B20:D260,3,1) -> 46322 | L19: =IF(K19>$N$2,"ADEQUADO AO RISCO","DIVERGENTE") -> ADEQUADO AO RISCO
A20: 20 | B20: JONATHAN DE SOUZA SILVA | C20: 6783404552 | D20: JOL4J67 | E20: AGREGADO | G20: 0.75 | H20: 06 PALETES | I20: 13M³ | J20: 4.000KG | K20: =VLOOKUP(Tabela2[[#This Row],[Motorista]],BUONNY!B21:D261,3,1) -> 45726 | L20: =IF(K20>$N$2,"ADEQUADO AO RISCO","DIVERGENTE") -> DIVERGENTE
A21: 21 | B21: JOSE CARLOS DOS R.S.NETO (netinho) | C21: 85517267572 | D21: EBM2G48 | E21: AGREGADO | F21: 71 98692-2580 | G21: 0.75 | H21: 08 PALETES | I21: 24M3 | J21: 4.000KG | K21: =VLOOKUP(Tabela2[[#This Row],[Motorista]],BUONNY!B22:D262,3,1) -> 46194 | L21: =IF(K21>$N$2,"ADEQUADO AO RISCO","DIVERGENTE") -> DIVERGENTE
A22: 22 | B22: JOSEMAN DE ALMEIDA E SILVA | C22: 81889755591 | D22: JQI2627 | E22: AGREGADO | F22: 71 99682-0577 | G22: 0.75 | H22: 10 PALETES | I22: 25M3 | J22: 4.000KG | K22: =VLOOKUP(Tabela2[[#This Row],[Motorista]],BUONNY!B23:D263,3,1) -> 46389 | L22: =IF(K22>$N$2,"ADEQUADO AO RISCO","DIVERGENTE") -> ADEQUADO AO RISCO
A23: 23 | B23: JOSLAN DELANO DE OLIVEIRA E SILVA | C23: 94840555591 | D23: JRE2F24 | E23: AGREGADO | F23: 71 99626-2827 | G23: 0.75 | H23: 08 PALETES | I23: 20M3 | J23: 4.000KG | K23: =VLOOKUP(Tabela2[[#This Row],[Motorista]],BUONNY!B24:D264,3,1) -> 46321 | L23: =IF(K23>$N$2,"ADEQUADO AO RISCO","DIVERGENTE") -> ADEQUADO AO RISCO
A24: 24 | B24: JOSMAR PEREIRA DE CASTRO | C24: 90569440530 | D24: NTH3G40 | E24: AGREGADO | G24: BONGO | H24: 02 PALLETS | I24: 6,5M³ | J24: 1500KG | K24: =VLOOKUP(Tabela2[[#This Row],[Motorista]],BUONNY!B25:D265,3,1) -> 46081 | L24: =IF(K24>$N$2,"ADEQUADO AO RISCO","DIVERGENTE") -> DIVERGENTE
A25: 25 | B25: LUIZ LOPES DOS SANTOS | C25: 465.212.085-00 | D25: HZX5810 | E25: AVULSO | F25: 71 99913-1288 | G25: TRUCK | H25: 14 PALETES | I25: 50M3 | J25: 15.000KG | K25: =VLOOKUP(Tabela2[[#This Row],[Motorista]],BUONNY!B26:D266,3,1) -> 46292 | L25: =IF(K25>$N$2,"ADEQUADO AO RISCO","DIVERGENTE") -> ADEQUADO AO RISCO
A26: 26 | B26: LUIZ CARLOS DA SILVA NASCIMENTO | C26: 77799470500 | D26: NYI4137 | E26: AGREGADO | F26: 71 98659-6800 | G26: BONGO | H26: 02 PALLETS | I26: 6,5M³ | J26: 1500KG | K26: =VLOOKUP(Tabela2[[#This Row],[Motorista]],BUONNY!B27:D267,3,1) -> 45989 | L26: =IF(K26>$N$2,"ADEQUADO AO RISCO","DIVERGENTE") -> DIVERGENTE
A27: 27 | B27: MANOEL LEAL DA SILVA | C27: 8877033568 | D27: BWT8A59 | E27: AGREGADO | F27: 71 99283-5000 | G27: 0.75 | H27: 06 PALETES | I27: 18M³ | J27: 3.300KG | K27: =VLOOKUP(Tabela2[[#This Row],[Motorista]],BUONNY!B28:D268,3,1) -> 46230 | L27: =IF(K27>$N$2,"ADEQUADO AO RISCO","DIVERGENTE") -> DIVERGENTE
A28: 28 | B28: MARCOS ANTONIO C. CLEMENTINO | C28: 4785270551 | D28: OZQ7034 | E28: AGREGADO | G28: BONGO | H28: 02 PALLETS | I28: 6,5M³ | J28: 1500KG | K28: =VLOOKUP(Tabela2[[#This Row],[Motorista]],BUONNY!B29:D269,3,1) -> 46356 | L28: =IF(K28>$N$2,"ADEQUADO AO RISCO","DIVERGENTE") -> ADEQUADO AO RISCO
A29: 29 | B29: MARCOS VINICIUS COSTA DOS SANTOS | C29: 5057170503 | D29: OZJ6A79 | E29: AGREGADO | G29: FIORINO | H29: 01 PALETE | I29: 1,9M³ | J29: 600KG | K29: =VLOOKUP(Tabela2[[#This Row],[Motorista]],BUONNY!B30:D270,3,1) -> 46340 | L29: =IF(K29>$N$2,"ADEQUADO AO RISCO","DIVERGENTE") -> ADEQUADO AO RISCO
A30: 30 | B30: MARIVALDO DOS SANTOS DE OLIVEIRA | C30: 62823442553 | D30: MYF3555 | E30: AGREGADO | F30: 71 98133-6791 | G30: TOCO | H30: 10 PALETES | I30: 33M³ | J30: 6.000KG | K30: =VLOOKUP(Tabela2[[#This Row],[Motorista]],BUONNY!B31:D271,3,1) -> 46155 | L30: =IF(K30>$N$2,"ADEQUADO AO RISCO","DIVERGENTE") -> DIVERGENTE
A31: 31 | B31: MATEUS DE JESUS DOS SANTOS | C31: 3953957554 | D31: JQB8H94 | E31: AGREGADO | F31: 71 99265-9621 | G31: 0.75 | H31: 06 PALETES | I31: 13M3 | J31: 3000KG | K31: =VLOOKUP(Tabela2[[#This Row],[Motorista]],BUONNY!B32:D272,3,1) -> 46291 | L31: =IF(K31>$N$2,"ADEQUADO AO RISCO","DIVERGENTE") -> ADEQUADO AO RISCO
A32: 32 | B32: NAILSON DE OLIVEIRA SOUZA | C32: 64766020553 | D32: NYV7789 | E32: AGREGADO | F32: 71 98504-5328 | G32: FIORINO | H32: 01 PALETE | I32: 1,9M³ | J32: 600KG | K32: =VLOOKUP(Tabela2[[#This Row],[Motorista]],BUONNY!B33:D273,3,1) -> 46138 | L32: =IF(K32>$N$2,"ADEQUADO AO RISCO","DIVERGENTE") -> DIVERGENTE
A33: 33 | B33: NILSON ARAUJO | C33: 54709733520 | D33: NME5H78 | E33: AGREGADO | F33: 71 99940-0718 | G33: TOCO | H33: 12 PALETES | I33: 40M³ | J33: 8.000KG | K33: =VLOOKUP(Tabela2[[#This Row],[Motorista]],BUONNY!B34:D274,3,1) -> 46302 | L33: =IF(K33>$N$2,"ADEQUADO AO RISCO","DIVERGENTE") -> ADEQUADO AO RISCO
A34: 34 | B34: RAFAEL CARVALHO DA SILVA | C34: 85896082512 | D34: OVC9379 | E34: AGREGADO | G34: BONGO | H34: 02 PALLETS | I34: 6,5M³ | J34: 1500KG | K34: =VLOOKUP(Tabela2[[#This Row],[Motorista]],BUONNY!B35:D275,3,1) -> 46042 | L34: =IF(K34>$N$2,"ADEQUADO AO RISCO","DIVERGENTE") -> DIVERGENTE
A35: 35 | B35: REINALDO XAVIER DE OLIVEIRA | C35: 91979587604 | D35: OLG4031 | E35: AGREGADO | F35: 71 98894-3876 | G35: FIORINO | H35: 01 PALETE | I35: 1,7M³ | J35: 600KG | K35: =VLOOKUP(Tabela2[[#This Row],[Motorista]],BUONNY!B36:D276,3,1) -> 46291 | L35: =IF(K35>$N$2,"ADEQUADO AO RISCO","DIVERGENTE") -> ADEQUADO AO RISCO
A36: 36 | B36: RIEDSON DOS SANTOS RAMOS | C36: 3660462500 | D36: JSU8734 | E36: AGREGADO | G36: FIORINO | H36: 01 PALETE | I36: 1,7M³ | J36: 600KG | K36: =VLOOKUP(Tabela2[[#This Row],[Motorista]],BUONNY!B37:D277,3,1) -> 46300 | L36: =IF(K36>$N$2,"ADEQUADO AO RISCO","DIVERGENTE") -> ADEQUADO AO RISCO
A37: 37 | B37: VAGNER GONCALVES PEREIRA | C37: 1232640573 | D37: PJW9B72 | E37: AGREGADO | G37: BONGO | H37: 02 PALLETS | I37: 8M³ | J37: 1500KG | K37: =VLOOKUP(Tabela2[[#This Row],[Motorista]],BUONNY!B2:D278,3,1) -> 46291 | L37: =IF(K37>$N$2,"ADEQUADO AO RISCO","DIVERGENTE") -> ADEQUADO AO RISCO
A38: 38 | B38: PEDRO TIAGO FRANCA DE OLIVEIRA | D38: IIZ7212 | E38: FROTA | F38: 71 98326-4918 | G38: 3/4 | H38: 06 PALETES | I38: 18M³ | J38: 3000KG | K38: =VLOOKUP(Tabela2[[#This Row],[Motorista]],BUONNY!B3:D279,3,1) -> 46540 | L38: =IF(K38>$N$2,"ADEQUADO AO RISCO","DIVERGENTE") -> ADEQUADO AO RISCO
A39: 39 | B39: CRISTOVAO JOSE XAVIER SILVA | C39: 693.705.404-15 | D39: IMP3J87 | E39: FROTA | G39: TRUCK | H39: 24 PALETES | I39: 80M³ | J39: 18.000KG | K39: =VLOOKUP(Tabela2[[#This Row],[Motorista]],BUONNY!B4:D280,3,1) -> 46323 | L39: =IF(K39>$N$2,"ADEQUADO AO RISCO","DIVERGENTE") -> ADEQUADO AO RISCO
A40: 40 | B40: MARCOS BITENCOURT DA SILVA | C40: 858.985.185-09 | D40: QYP6I13 | E40: FROTA | F40: 71 99978-6237 | G40: 3/4 | H40: 08 PALETES | I40: 30M³ | K40: =VLOOKUP(Tabela2[[#This Row],[Motorista]],BUONNY!B5:D281,3,1) -> 46356 | L40: =IF(K40>$N$2,"ADEQUADO AO RISCO","DIVERGENTE") -> ADEQUADO AO RISCO
...

Sheet FROTA-AGREG
B2: MOTORISTAS CASA | C2: PLACA | D2: TIPO | E2: REGIÃO | F2: ENTREGAS | G2: PESO CALC. | H2: M³ | I2: VOLUME | J2: FRETE REAL | K2: CAPACIDADE | L2: OCUPAÇÃO | M2: FRETE | N2: RENTABILIDADE
B3: PAULO HENRIQUE REIS | C3: SKG0C50 | D3: TRUCK | K3: 73 | L3: =(H3/K3)*100 -> 0 | N3: =1-(M3/J3) -> #DIV/0!
B4: MARCOS BITENCOURT | C4: QYP6I13 | D4: 0.75 | E4: ALAGOINHAS/COITÉ | F4: 12 | G4: 7502.719 | H4: 25.212113 | I4: 1147 | J4: 6076.05 | K4: 30 | L4: =(H4/K4)*100 -> 84.040378 | M4: 2151.66 | N4: =1-(M4/J4) -> 0.64587849
B5: MAURICIO SILVA | C5: QYO9B52 | D5: TOCO | K5: 40 | L5: =(H5/K5)*100 -> 0 | N5: =1-(M5/J5) -> #DIV/0!
B6: VERINALDO BATISTA | C6: NZB7A98 | D6: TRUCK | K6: 55 | L6: =(H6/K6)*100 -> 0 | N6: =1-(M6/J6) -> #DIV/0!
B7: RIELSON DIAS | C7: IVD0C35 | D7: TOCO | K7: 55 | L7: =(H7/K7)*100 -> 0 | N7: =1-(M7/J7) -> #DIV/0!
B8: RAMILER CERQUEIRA | C8: ILI4E91 | D8: CARRETA | K8: 100 | L8: =(H8/K8)*100 -> 0 | N8: =1-(M8/J8) -> #DIV/0!
B9: JOSE CLEBER | C9: SKG6F77 | D9: TRUCK | K9: 73 | L9: =(H9/K9)*100 -> 0 | N9: =1-(M9/J9) -> #DIV/0!
B10: LUCAS SANTOS | C10: AQT1E59 | D10: TRUCK | K10: 71 | L10: =(H10/K10)*100 -> 0 | N10: =1-(M10/J10) -> #DIV/0!
B11: ARGONIO CARVALHO | C11: AUM2D96 | D11: TOCO | K11: 50 | L11: =(H11/K11)*100 -> 0 | N11: =1-(M11/J11) -> #DIV/0!
B12: RAILAN BISPO | C12: ITC1E10 | D12: 0.75 | K12: 30 | L12: =(H12/K12)*100 -> 0 | N12: =1-(M12/J12) -> #DIV/0!
B13: MARCOS BITENCOURT | C13: IIZ7212 | D13: 0.75 | K13: 18 | L13: =(H13/K13)*100 -> 0 | N13: =1-(M13/J13) -> #DIV/0!
B14: PEDRO TIAGO | C14: QYM7B91 | D14: SPRINTER | K14: 10 | L14: =(H14/K14)*100 -> 0 | N14: =1-(M14/J14) -> #DIV/0!
B15: EVALDO FERREIRA | C15: JSZ2G59 | D15: SAVEIRO | K15: 2.5 | L15: =(H15/K15)*100 -> 0 | N15: =1-(M15/J15) -> #DIV/0!
B16: ANDESON SENA | C16: TMO7D89 | D16: 0.75 | K16: 25 | L16: =(H16/K16)*100 -> 0 | N16: =1-(M16/J16) -> #DIV/0!
B17: JOSE CRISTOVAO | C17: IMP3J87 | D17: TRUCK | K17: 80 | L17: =(H17/K17)*100 -> 0 | N17: =1-(M17/J17) -> #DIV/0!
B18: PEDRO HENRIQUE | C18: UHV2C66 | D18: TRUCK | K18: 52 | L18: =(H18/K18)*100 -> 0 | N18: =1-(M18/J18) -> #DIV/0!
B19: VICTOR EDUARDO | C19: UHV2E66 | D19: TRUCK | K19: 52 | L19: =(H19/K19)*100 -> 0 | N19: =1-(M19/J19) -> #DIV/0!
B20: JOAO PAULO | C20: UHV2E06 | D20: TRUCK | K20: 52 | L20: =(H20/K20)*100 -> 0 | N20: =1-(M20/J20) -> #DIV/0!
B22: AGREGADOS/AVULSO | C22: PLACA | D22: TIPO
B23: ELIAS ANJOS | C23: PKT2D93 | D23: 46115 | K23: 30 | L23: =(H23/K23)*100 -> 0 | N23: =1-(M23/J23) -> #DIV/0!
B24: DANILO QUEIROZ | D24: CARRETA | K24: 100 | L24: =(H24/K24)*100 -> 0 | N24: =1-(M24/J24) -> #DIV/0!
B25: AUGUSTO RIBEIRO | C25: JQS5E79 | D25: 0.75 | K25: 26 | L25: =(H25/K25)*100 -> 0 | N25: =1-(M25/J25) -> #DIV/0!
B26: ROMULO COSTA | C26: GUI TRANSP | D26: 0.75 | K26: 30 | L26: =(H26/K26)*100 -> 0 | N26: =1-(M26/J26) -> #DIV/0!
B27: TERENCIO GOMES | C27: NZB5H06 | D27: TOCO | K27: 45 | L27: =(H27/K27)*100 -> 0 | N27: =1-(M27/J27) -> #DIV/0!
B28: MARIVALDO COSTA | D28: TRUCK | K28: 50 | L28: =(H28/K28)*100 -> 0 | N28: =1-(M28/J28) -> #DIV/0!
B29: PAULO ROBERTO | D29: 0.75 | K29: 30 | L29: =(H29/K29)*100 -> 0 | N29: =1-(M29/J29) -> #DIV/0!
B30: LUIZ LOPES | C30: HZX5810 | D30: TRUCK | K30: 45 | L30: =(H30/K30)*100 -> 0 | N30: =1-(M30/J30) -> #DIV/0!
B31: AGNALDO MATOS | C31: NMA9D16 | D31: TOCO | K31: 45 | L31: =(H31/K31)*100 -> 0 | N31: =1-(M31/J31) -> #DIV/0!
B32: FRANCKLIM SANTOS | D32: CARRETA | K32: 100 | L32: =(H32/K32)*100 -> 0 | N32: =1-(M32/J32) -> #DIV/0!
B33: RONILTON DOS SANTOS | C33: LVB6J83 | D33: TOCO | E33: FSA/IPIRÁ | F33: 3 | G33: 11383.147 | H33: 40.313603 | I33: 2034 | J33: 10156.046 | K33: 46 | L33: =(H33/K33)*100 -> 87.638268 | M33: 2200 | N33: =1-(M33/J33) -> 0.78338026
B34: MARIVALDO DOS SANTOS | C34: MYF3555 | D34: TOCO | K34: 33 | L34: =(H34/K34)*100 -> 0 | N34: =1-(M34/J34) -> #DIV/0!
B35: MARCIO DE OLIVEIRA | D35: CARRETA | E35: TEIXEIRA DE FREITAS | F35: 1 | G35: 15069.262 | H35: 51.763723 | I35: 1294 | J35: 17171.205 | K35: 105 | L35: =(H35/K35)*100 -> 49.298784 | M35: =G35*0.3 -> 4520.7786 | N35: =1-(M35/J35) -> 0.73672328
B36: NILVÃ AGUIAR | D36: TRUCK | K36: 59 | L36: =(H36/K36)*100 -> 0 | N36: =1-(M36/J36) -> #DIV/0!
B37: JORGE SANTOS | C37: BTT4792 | D37: TRUCK | K37: 60 | L37: =(H37/K37)*100 -> 0 | N37: =1-(M37/J37) -> #DIV/0!
B38: RICARDO OLEGARIO | C38: EYQ9B59 | D38: CARRETA | K38: 113 | L38: =(H38/K38)*100 -> 0 | N38: =1-(M38/J38) -> #DIV/0!
B39: LINDOMAR SOUZA | C39: CLK6104 | D39: TRUCK | K39: 76 | L39: =(H39/K39)*100 -> 0 | N39: =1-(M39/J39) -> #DIV/0!
B40: DENIVISON REGO | C40: DEX0B37 | D40: TOCO | K40: 50 | L40: =(H40/K40)*100 -> 0 | N40: =1-(M40/J40) -> #DIV/0!
B41: ANTONIO MARCOS | C41: JOA5C32 | D41: TOCO | K41: 44 | L41: =(H41/K41)*100 -> 0 | N41: =1-(M41/J41) -> #DIV/0!
B42: MADSON DE SANTANA | C42: QPX5E24 | D42: 0.75 | K42: 30 | L42: =(H42/K42)*100 -> 0 | N42: =1-(M42/J42) -> #DIV/0!
...

Sheet BUONNY
A1: Documento | B1: Nome | C1: Tipo Profissional | D1: Data de Expiração da Ultima Analíse | E1: Tipo do Contrato | F1: Status da Renovação da analíse | G1: Opção de Renovação | H1: Inclusão da Analíse
A2: 92984371534 | B2: ADELMO CHILENO GOMES DOS SANTOS | C2: Motorista | D2: 46267 | E2: Agregado | F2: Aguardando expiração | G2: Nunca Renovar | H2: 46087.56
A3: 90541022504 | B3: ADEMILTON PEREIRA DOS SANTOS | C3: Motorista | D3: 46155 | E3: Agregado | F3: Aguardando expiração | G3: Nunca Renovar | H3: 45975.04
A4: 11029723559 | B4: ADILTON OLIVEIRA DA MOTA JUNIOR | C4: Motorista | D4: 46207 | E4: Agregado | F4: Aguardando expiração | G4: Nunca Renovar | H4: 46027.428
A5: 60625333500 | B5: ADRIANO VIEIRA DOS SANTOS | C5: Motorista | D5: 46252 | E5: Agregado | F5: Aguardando expiração | G5: Nunca Renovar | H5: 46072.998
A6: 1672732565 | B6: AGNALDO DOS SANTOS | C6: Motorista | D6: 46175 | E6: Agregado | F6: Aguardando expiração | G6: Nunca Renovar | H6: 45995.056
A7: 42229006568 | B7: AGNALDO FLORENTINO DE JESUS | C7: Motorista | D7: 46155 | E7: Agregado | F7: Aguardando expiração | G7: Nunca Renovar | H7: 45975.015
A8: 27638537572 | B8: AGNALDO MATOS DOS SANTOS | C8: Motorista | D8: 46258 | E8: Agregado | F8: Aguardando expiração | G8: Nunca Renovar | H8: 46078.812
A9: 86753541500 | B9: AGNALDO PEREIRA BRITO | C9: Motorista | D9: 46139 | E9: Agregado | F9: Aguardando expiração | G9: Nunca Renovar | H9: 45959.849
A10: 91634210549 | B10: AGNALDO PEREIRA DOS SANTOS | C10: Motorista | D10: 46281 | E10: Agregado | F10: Aguardando expiração | G10: Nunca Renovar | H10: 46101.806
A11: 86073779577 | B11: AILTON DEIVID DOS REIS SILVA | C11: Motorista | D11: 46223 | E11: Agregado | F11: Aguardando expiração | G11: Nunca Renovar | H11: 46043.472
A12: 9115100529 | B12: ALAN DELON SOUSA DOS SANTOS | C12: Motorista | D12: 46321 | E12: Agregado | F12: Aguardando expiração | G12: Nunca Renovar | H12: 46141.535
A13: 1983960586 | B13: ALAN LOBO ALMEIDA | C13: Motorista | D13: 46340 | E13: Agregado | F13: Aguardando expiração | G13: Nunca Renovar | H13: 46160.606
... A263: 10608251550 | B263: YURI NOVAES DOS SANTOS | C263: Motorista | D263: 46021 | E263: Agregado | F263: Aguardando expiração | G263: Nunca Renovar | H263: 45841.725

Sheet ORDEM DE CARREGAMENTO
A1: ORDEM DE CARREGAMENTO
N5: OC Nº YYYY0728-0855
A7: DATA DA EMISSÃO | E7: DATA DO CARREGAMENTO | I7: TIPO DE OPERAÇÃO | K7: SIGLA | L7: Nº: | M7: UNIDADE / CD
I8: ENTREGA | L8: 78 | M8: BNRV – Unidade SSA
A9: DADOS DO VEÍCULO E MOTORISTA
A10: MOTORISTA | G10: CPF | L10: TELEFONE / CONTATO
A11: =IFERROR(UPPER(VLOOKUP(L8,base!A:I,2,0)),"") -> RONILTON DOS SANTOS | G11: =IFERROR(UPPER(VLOOKUP(L8,base!A:I,3,0)),"") -> 743.280.505-91 | L11: =IFERROR(UPPER(VLOOKUP(L8,base!A:I,6,0)),"") -> 71 99716-2851
A12: PLACA CAVALO | D12: PLACA CARRETA | G12: TIPO DE VEÍCULO | J12: CUBAGEM VEÍCULO | M12: QTD. PALLETS | O12: VÍNCULO
A13: =IFERROR(UPPER(VLOOKUP(L8,base!A:I,4,0)),"") -> LVB6J83 | G13: =IFERROR(UPPER(VLOOKUP(L8,base!A:I,7,0)),"") -> TOCO | J13: =IFERROR(UPPER(VLOOKUP(L8,base!A:I,9,0)),"") -> 46M³ | O13: FROTA
A14: DADOS DO CARREGAMENTO
A15: CONFERENTE RESPONSÁVEL | E15: AJUDANTES | I15: DOCA | K15: TURNO | M15: HORA INÍCIO | O15: HORA FIM
A17: QTD. VOLUMES CARREGADOS | E17: QTD TOTAL DE PALETES | I17: TIPO DE CARGA
I18: □ BATIDA □ PALETIZADA □ MISTA
A19: CHECKLIST DE CARREGAMENTO
A20: □ | B20: Documentação da carga conferida | F20: □ | G20: Quantidade de paletes conferida | K20: □ | L20: Lacre do veículo aplicado
A21: □ | B21: Notas fiscais conferidas | F21: □ | G21: Tipo de carga correto (batida/paletizada) | K21: □ | L21: Veículo limpo e em condições
A22: □ | B22: Quantidade de volumes conferida | F22: □ | G22: Doca correta utilizada | K22: □ | L22: Hora de saída registrada
A23: NÚMERO DO LACRE:
A24: RESUMO DA CARGA
A25: TOTAL DE CTRCs | E25: TOTAL DE VOLUMES | F25: TOTAL PESO REAL | I25: TOTAL CUBAGEM (m³) | M25: TOTAL PESO CALC
A26: =COUNTA(H30:H59) -> 3 | E26: =SUM(N30:N59) -> 1332 | F26: =SUM(J30:J59) -> 5232.718 | I26: =SUM(L30:M59) -> 22.6445 | M26: =SUM(K30:K59) -> 6471.225
A27: NOTAS FISCAIS / ITENS CARREGADOS
A28: ORD. | B28: SETOR | C28: DESTINATÁRIO | F28: CIDADE | H28: NOTA FISCAL | I28: AGENDA | J28: PESO | K28: PESO | L28: CUBAGEM (M³) | N28: VOLUME | O28: QTD PALETES | P28: OBS.
B29: (ROTA) | J29: REAL(KG) | K29: CALC. (KG)
A30: 1 | B30: JEQ | C30: 57117138 CAROLINE DA SILVA FER | F30: SANTO ESTEVAO | H30: 294675* | J30: 372.118 | K30: 1610.625 | L30: 6.4425 | N30: 242
A31: 2 | B31: IRE | C31: DISTRIBUIDORA DE COSMETICOS AN | F31: IPIRA | H31: 12651* | I31: 46248 | J31: 3758.1 | K31: 3758.1 | L31: 12.527 | N31: 985 | O31: 7
A32: 3 | B32: IRE | C32: DISTRIBUIDORA DE COSMETICOS AN | F32: IPIRA | H32: 12667 | I32: 46248 | J32: 1102.5 | K32: 1102.5 | L32: 3.675 | N32: 105 | O32: 2
A33: 4
A34: 5
A35: 6
A36: 7
A37: 8
A38: 9
A39: 10
A40: 11
A41: 12
A42: 13
A43: 14
A44: 15
... A59: 30
...
